Workbook

Sheet SAEB_original
A1: ID | B1: NOM_MUN | C1: COD_IBGE | D1: SAEB15_LP_5 | E1: SAEB15_MT_5 | F1: SAEB15_LP_9 | G1: SAEB15_MT_9 | H1: SAEB17_LP_5 | I1: SAEB17_MT_5 | J1: SAEB17_LP_9 | K1: SAEB17_MT_9 | L1: SAEB19_LP_5 | M1: SAEB19_MT_5 | N1: SAEB19_LP_9 | O1: SAEB19_MT_9 | P1: SAEB21_LP_5 | Q1: SAEB21_MT_5 | R1: SAEB21_LP_9 | S1: SAEB21_MT_9 | T1: SAEB23_LP_5 | U1: SAEB23_MT_5 | V1: SAEB23_LP_9 | W1: SAEB23_MT_9 | X1: TOTAL_LP_5 | Y1: TOTAL_MT_5 | Z1: TOTAL_LP_9 | AA1: TOTAL_MT_9
A2: 1 | B2: Açucena | C2: 3100500 | D2: #N/A | E2: #N/A | F2: #N/A | G2: #N/A | H2: 201.03 | I2: 228.8 | J2: 266.95 | K2: 250.53 | L2: 217.6 | M2: 232.66 | N2: 268.55 | O2: 266.49 | P2: 183.35 | Q2: 184.5 | R2: 0 | S2: 0 | T2: 0 | U2: 0 | V2: 238.41 | W2: 247.05 | X2: =COUNTIFS(H2,">0",L2,">0",P2,">0",T2,">0") -> 0 | Y2: =COUNTIFS(I2,">0",M2,">0",Q2,">0",U2,">0") -> 0 | Z2: =COUNTIFS(J2,">0",N2,">0",R2,">0",V2,">0") -> 0 | AA2: =COUNTIFS(K2,">0",O2,">0",S2,">0",W2,">0") -> 0
A3: 2 | B3: Água Boa | C3: 3100609 | D3: #N/A | E3: #N/A | F3: #N/A | G3: #N/A | H3: #N/A | I3: #N/A | J3: #N/A | K3: #N/A | L3: 214.57 | M3: 243.88 | N3: 0 | O3: 0 | P3: #N/A | Q3: #N/A | R3: #N/A | S3: #N/A | T3: 187.28 | U3: 211.1 | V3: 0 | W3: 0 | X3: =COUNTIFS(H3,">0",L3,">0",P3,">0",T3,">0") -> 0 | Y3: =COUNTIFS(I3,">0",M3,">0",Q3,">0",U3,">0") -> 0 | Z3: =COUNTIFS(J3,">0",N3,">0",R3,">0",V3,">0") -> 0 | AA3: =COUNTIFS(K3,">0",O3,">0",S3,">0",W3,">0") -> 0
A4: 3 | B4: Águas Formosas | C4: 3100906 | D4: 0 | E4: 0 | F4: 233.65 | G4: 237.53 | H4: 194.22 | I4: 206.59 | J4: 248.51 | K4: 231.5 | L4: 189.35 | M4: 192.54 | N4: 243.02 | O4: 241.49 | P4: #N/A | Q4: #N/A | R4: #N/A | S4: #N/A | T4: 194.57 | U4: 185.96 | V4: 0 | W4: 0 | X4: =COUNTIFS(H4,">0",L4,">0",P4,">0",T4,">0") -> 0 | Y4: =COUNTIFS(I4,">0",M4,">0",Q4,">0",U4,">0") -> 0 | Z4: =COUNTIFS(J4,">0",N4,">0",R4,">0",V4,">0") -> 0 | AA4: =COUNTIFS(K4,">0",O4,">0",S4,">0",W4,">0") -> 0
A5: 4 | B5: Águas Vermelhas | C5: 3101003 | D5: 190.53 | E5: 201.16 | F5: 0 | G5: 0 | H5: 213.62 | I5: 219.48 | J5: 0 | K5: 0 | L5: 224.73 | M5: 238.65 | N5: 0 | O5: 0 | P5: 189.56 | Q5: 196.52 | R5: 0 | S5: 0 | T5: 205.68 | U5: 214.12 | V5: 0 | W5: 0 | X5: =COUNTIFS(H5,">0",L5,">0",P5,">0",T5,">0") -> 1 | Y5: =COUNTIFS(I5,">0",M5,">0",Q5,">0",U5,">0") -> 1 | Z5: =COUNTIFS(J5,">0",N5,">0",R5,">0",V5,">0") -> 0 | AA5: =COUNTIFS(K5,">0",O5,">0",S5,">0",W5,">0") -> 0
A6: 5 | B6: Aimorés | C6: 3101102 | D6: 216.28 | E6: 220.1 | F6: 271.5 | G6: 269.26 | H6: 220.05 | I6: 229.35 | J6: 253.67 | K6: 253.32 | L6: 224.19 | M6: 229.53 | N6: 251.44 | O6: 261.31 | P6: 208.12 | Q6: 211.47 | R6: 253.3 | S6: 253.68 | T6: 215.43 | U6: 219.95 | V6: 260.97 | W6: 253.11 | X6: =COUNTIFS(H6,">0",L6,">0",P6,">0",T6,">0") -> 1 | Y6: =COUNTIFS(I6,">0",M6,">0",Q6,">0",U6,">0") -> 1 | Z6: =COUNTIFS(J6,">0",N6,">0",R6,">0",V6,">0") -> 1 | AA6: =COUNTIFS(K6,">0",O6,">0",S6,">0",W6,">0") -> 1
A7: 6 | B7: Almenara | C7: 3101706 | D7: 187.96 | E7: 199.75 | F7: 253.03 | G7: 242.33 | H7: 192.82 | I7: 195.55 | J7: 252.04 | K7: 245.38 | L7: 190.15 | M7: 200.24 | N7: 257.31 | O7: 239.91 | P7: 191.34 | Q7: 199.1 | R7: 253.66 | S7: 237.69 | T7: 195.77 | U7: 204.06 | V7: 241.06 | W7: 229.53 | X7: =COUNTIFS(H7,">0",L7,">0",P7,">0",T7,">0") -> 1 | Y7: =COUNTIFS(I7,">0",M7,">0",Q7,">0",U7,">0") -> 1 | Z7: =COUNTIFS(J7,">0",N7,">0",R7,">0",V7,">0") -> 1 | AA7: =COUNTIFS(K7,">0",O7,">0",S7,">0",W7,">0") -> 1
A8: 7 | B8: Alpercata | C8: 3101805 | D8: 199.05 | E8: 210.96 | F8: 226.71 | G8: 247.11 | H8: 177.33 | I8: 189.95 | J8: 259 | K8: 253.75 | L8: 199.27 | M8: 211.38 | N8: 233.06 | O8: 255.11 | P8: 191.83 | Q8: 205.35 | R8: 246.33 | S8: 250 | T8: 195.88 | U8: 198.73 | V8: 243.6 | W8: 246.09 | X8: =COUNTIFS(H8,">0",L8,">0",P8,">0",T8,">0") -> 1 | Y8: =COUNTIFS(I8,">0",M8,">0",Q8,">0",U8,">0") -> 1 | Z8: =COUNTIFS(J8,">0",N8,">0",R8,">0",V8,">0") -> 1 | AA8: =COUNTIFS(K8,">0",O8,">0",S8,">0",W8,">0") -> 1
A9: 8 | B9: Alvarenga | C9: 3102209 | D9: 181.79 | E9: 215.74 | F9: 0 | G9: 0 | H9: 213.14 | I9: 222.73 | J9: 0 | K9: 0 | L9: 201.97 | M9: 217.98 | N9: 0 | O9: 0 | P9: #N/A | Q9: #N/A | R9: #N/A | S9: #N/A | T9: 199.47 | U9: 211.1 | V9: 0 | W9: 0 | X9: =COUNTIFS(H9,">0",L9,">0",P9,">0",T9,">0") -> 0 | Y9: =COUNTIFS(I9,">0",M9,">0",Q9,">0",U9,">0") -> 0 | Z9: =COUNTIFS(J9,">0",N9,">0",R9,">0",V9,">0") -> 0 | AA9: =COUNTIFS(K9,">0",O9,">0",S9,">0",W9,">0") -> 0
A10: 9 | B10: Angelândia | C10: 3102852 | D10: 214.97 | E10: 237.37 | F10: 0 | G10: 0 | H10: 205.97 | I10: 215.57 | J10: 0 | K10: 0 | L10: 214.58 | M10: 235.89 | N10: 0 | O10: 0 | P10: 181.85 | Q10: 208.94 | R10: 0 | S10: 0 | T10: 215.01 | U10: 227.73 | V10: 0 | W10: 0 | X10: =COUNTIFS(H10,">0",L10,">0",P10,">0",T10,">0") -> 1 | Y10: =COUNTIFS(I10,">0",M10,">0",Q10,">0",U10,">0") -> 1 | Z10: =COUNTIFS(J10,">0",N10,">0",R10,">0",V10,">0") -> 0 | AA10: =COUNTIFS(K10,">0",O10,">0",S10,">0",W10,">0") -> 0
A11: 10 | B11: Araçuaí | C11: 3103405 | D11: 188.82 | E11: 192.21 | F11: 228.91 | G11: 239.08 | H11: 201.51 | I11: 209.14 | J11: 245.28 | K11: 243.43 | L11: 195.62 | M11: 203.67 | N11: 241.91 | O11: 228.37 | P11: 180.92 | Q11: 188.92 | R11: 230.15 | S11: 222.58 | T11: 196.17 | U11: 205.92 | V11: 239.34 | W11: 220.47 | X11: =COUNTIFS(H11,">0",L11,">0",P11,">0",T11,">0") -> 1 | Y11: =COUNTIFS(I11,">0",M11,">0",Q11,">0",U11,">0") -> 1 | Z11: =COUNTIFS(J11,">0",N11,">0",R11,">0",V11,">0") -> 1 | AA11: =COUNTIFS(K11,">0",O11,">0",S11,">0",W11,">0") -> 1
A12: 11 | B12: Aricanduva | C12: 3104452 | D12: 211.97 | E12: 215.88 | F12: 0 | G12: 0 | H12: 222.21 | I12: 238.95 | J12: 0 | K12: 0 | L12: 228.01 | M12: 250.16 | N12: 0 | O12: 0 | P12: 197.66 | Q12: 197.69 | R12: 0 | S12: 0 | T12: 211.63 | U12: 226.58 | V12: 0 | W12: 0 | X12: =COUNTIFS(H12,">0",L12,">0",P12,">0",T12,">0") -> 1 | Y12: =COUNTIFS(I12,">0",M12,">0",Q12,">0",U12,">0") -> 1 | Z12: =COUNTIFS(J12,">0",N12,">0",R12,">0",V12,">0") -> 0 | AA12: =COUNTIFS(K12,">0",O12,">0",S12,">0",W12,">0") -> 0
A13: 12 | B13: Arinos | C13: 3104502 | D13: 203.92 | E13: 212.94 | F13: 0 | G13: 0 | H13: 200.62 | I13: 206.21 | J13: 227.81 | K13: 227.1 | L13: 204.26 | M13: 214.96 | N13: 264.56 | O13: 249.8 | P13: 186.49 | Q13: 187.2 | R13: 239.9 | S13: 235.17 | T13: 203 | U13: 203.34 | V13: 231.82 | W13: 225.52 | X13: =COUNTIFS(H13,">0",L13,">0",P13,">0",T13,">0") -> 1 | Y13: =COUNTIFS(I13,">0",M13,">0",Q13,">0",U13,">0") -> 1 | Z13: =COUNTIFS(J13,">0",N13,">0",R13,">0",V13,">0") -> 1 | AA13: =COUNTIFS(K13,">0",O13,">0",S13,">0",W13,">0") -> 1
A14: 13 | B14: Ataléia | C14: 3104700 | D14: 198.89 | E14: 220.24 | F14: 0 | G14: 0 | H14: 209.45 | I14: 210.48 | J14: 240.31 | K14: 241.36 | L14: 199.69 | M14: 209.27 | N14: 0 | O14: 0 | P14: 181.38 | Q14: 190.36 | R14: 231.75 | S14: 232.05 | T14: 189.3 | U14: 206.4 | V14: 214.86 | W14: 212.43 | X14: =COUNTIFS(H14,">0",L14,">0",P14,">0",T14,">0") -> 1 | Y14: =COUNTIFS(I14,">0",M14,">0",Q14,">0",U14,">0") -> 1 | Z14: =COUNTIFS(J14,">0",N14,">0",R14,">0",V14,">0") -> 0 | AA14: =COUNTIFS(K14,">0",O14,">0",S14,">0",W14,">0") -> 0
A15: 14 | B15: Augusto de Lima | C15: 3104809 | D15: 200.62 | E15: 207.92 | F15: 233.69 | G15: 242.28 | H15: 191.25 | I15: 198.83 | J15: 274.75 | K15: 259.76 | L15: 205.97 | M15: 221.5 | N15: 261.03 | O15: 256.6 | P15: #N/A | Q15: #N/A | R15: #N/A | S15: #N/A | T15: 196.65 | U15: 210.84 | V15: 252.58 | W15: 252.04 | X15: =COUNTIFS(H15,">0",L15,">0",P15,">0",T15,">0") -> 0 | Y15: =COUNTIFS(I15,">0",M15,">0",Q15,">0",U15,">0") -> 0 | Z15: =COUNTIFS(J15,">0",N15,">0",R15,">0",V15,">0") -> 0 | AA15: =COUNTIFS(K15,">0",O15,">0",S15,">0",W15,">0") -> 0
A16: 15 | B16: Bandeira | C16: 3105202 | D16: 206.42 | E16: 213.59 | F16: 0 | G16: 0 | H16: 221.48 | I16: 232.52 | J16: 249.66 | K16: 247.25 | L16: 202.24 | M16: 213.17 | N16: 0 | O16: 0 | P16: 191.48 | Q16: 205.92 | R16: 0 | S16: 0 | T16: 211.02 | U16: 223.46 | V16: 253.12 | W16: 242.8 | X16: =COUNTIFS(H16,">0",L16,">0",P16,">0",T16,">0") -> 1 | Y16: =COUNTIFS(I16,">0",M16,">0",Q16,">0",U16,">0") -> 1 | Z16: =COUNTIFS(J16,">0",N16,">0",R16,">0",V16,">0") -> 0 | AA16: =COUNTIFS(K16,">0",O16,">0",S16,">0",W16,">0") -> 0
A17: 16 | B17: Berilo | C17: 3106507 | D17: #N/A | E17: #N/A | F17: #N/A | G17: #N/A | H17: #N/A | I17: #N/A | J17: #N/A | K17: #N/A | L17: 198.84 | M17: 212.22 | N17: 0 | O17: 0 | P17: #N/A | Q17: #N/A | R17: #N/A | S17: #N/A | T17: #N/A | U17: #N/A | V17: #N/A | W17: #N/A | X17: =COUNTIFS(H17,">0",L17,">0",P17,">0",T17,">0") -> 0 | Y17: =COUNTIFS(I17,">0",M17,">0",Q17,">0",U17,">0") -> 0 | Z17: =COUNTIFS(J17,">0",N17,">0",R17,">0",V17,">0") -> 0 | AA17: =COUNTIFS(K17,">0",O17,">0",S17,">0",W17,">0") -> 0
A18: 17 | B18: Berizal | C18: 3106655 | D18: 194.61 | E18: 202.95 | F18: 0 | G18: 0 | H18: 215.55 | I18: 212.05 | J18: 0 | K18: 0 | L18: 209.84 | M18: 225.58 | N18: 0 | O18: 0 | P18: 202.18 | Q18: 212.89 | R18: 0 | S18: 0 | T18: 209.71 | U18: 228.27 | V18: 0 | W18: 0 | X18: =COUNTIFS(H18,">0",L18,">0",P18,">0",T18,">0") -> 1 | Y18: =COUNTIFS(I18,">0",M18,">0",Q18,">0",U18,">0") -> 1 | Z18: =COUNTIFS(J18,">0",N18,">0",R18,">0",V18,">0") -> 0 | AA18: =COUNTIFS(K18,">0",O18,">0",S18,">0",W18,">0") -> 0
A19: 18 | B19: Bertópolis | C19: 3106606 | D19: 215.1 | E19: 223.2 | F19: 0 | G19: 0 | H19: 213.28 | I19: 216.07 | J19: 0 | K19: 0 | L19: 213.35 | M19: 225.79 | N19: 0 | O19: 0 | P19: #N/A | Q19: #N/A | R19: #N/A | S19: #N/A | T19: 207.88 | U19: 212.32 | V19: 0 | W19: 0 | X19: =COUNTIFS(H19,">0",L19,">0",P19,">0",T19,">0") -> 0 | Y19: =COUNTIFS(I19,">0",M19,">0",Q19,">0",U19,">0") -> 0 | Z19: =COUNTIFS(J19,">0",N19,">0",R19,">0",V19,">0") -> 0 | AA19: =COUNTIFS(K19,">0",O19,">0",S19,">0",W19,">0") -> 0
A20: 19 | B20: Bocaiúva | C20: 3107307 | D20: 188.29 | E20: 202.76 | F20: 238.45 | G20: 240.66 | H20: 200.2 | I20: 211.93 | J20: 235.38 | K20: 235.91 | L20: 197.37 | M20: 207.88 | N20: 233.59 | O20: 240.32 | P20: 189.88 | Q20: 204.9 | R20: 236.96 | S20: 235.85 | T20: 190.3 | U20: 203.13 | V20: 239.62 | W20: 233.84 | X20: =COUNTIFS(H20,">0",L20,">0",P20,">0",T20,">0") -> 1 | Y20: =COUNTIFS(I20,">0",M20,">0",Q20,">0",U20,">0") -> 1 | Z20: =COUNTIFS(J20,">0",N20,">0",R20,">0",V20,">0") -> 1 | AA20: =COUNTIFS(K20,">0",O20,">0",S20,">0",W20,">0") -> 1
A21: 20 | B21: Bonfinópolis de Minas | C21: 3108206 | D21: 220.02 | E21: 229.66 | F21: 269.95 | G21: 270.3 | H21: 218.32 | I21: 234.51 | J21: 260.7 | K21: 252.85 | L21: 216.87 | M21: 220.35 | N21: 252.66 | O21: 266.72 | P21: 198.62 | Q21: 210.16 | R21: 259.67 | S21: 257.82 | T21: 210.08 | U21: 215.33 | V21: 275.34 | W21: 274.58 | X21: =COUNTIFS(H21,">0",L21,">0",P21,">0",T21,">0") -> 1 | Y21: =COUNTIFS(I21,">0",M21,">0",Q21,">0",U21,">0") -> 1 | Z21: =COUNTIFS(J21,">0",N21,">0",R21,">0",V21,">0") -> 1 | AA21: =COUNTIFS(K21,">0",O21,">0",S21,">0",W21,">0") -> 1
A22: 21 | B22: Bonito de Minas | C22: 3108255 | D22: 191.77 | E22: 193.92 | F22: 0 | G22: 0 | H22: 194.47 | I22: 191.09 | J22: 225 | K22: 216.37 | L22: 196.59 | M22: 202.04 | N22: 211.16 | O22: 199.2 | P22: #N/A | Q22: #N/A | R22: #N/A | S22: #N/A | T22: 198.67 | U22: 201.7 | V22: 214.6 | W22: 196.74 | X22: =COUNTIFS(H22,">0",L22,">0",P22,">0",T22,">0") -> 0 | Y22: =COUNTIFS(I22,">0",M22,">0",Q22,">0",U22,">0") -> 0 | Z22: =COUNTIFS(J22,">0",N22,">0",R22,">0",V22,">0") -> 0 | AA22: =COUNTIFS(K22,">0",O22,">0",S22,">0",W22,">0") -> 0
A23: 22 | B23: Botumirim | C23: 3108503 | D23: #N/A | E23: #N/A | F23: #N/A | G23: #N/A | H23: 167.82 | I23: 177.47 | J23: 249.71 | K23: 240.34 | L23: 186.62 | M23: 211.91 | N23: 0 | O23: 0 | P23: #N/A | Q23: #N/A | R23: #N/A | S23: #N/A | T23: 160.26 | U23: 179.81 | V23: 231.36 | W23: 237.29 | X23: =COUNTIFS(H23,">0",L23,">0",P23,">0",T23,">0") -> 0 | Y23: =COUNTIFS(I23,">0",M23,">0",Q23,">0",U23,">0") -> 0 | Z23: =COUNTIFS(J23,">0",N23,">0",R23,">0",V23,">0") -> 0 | AA23: =COUNTIFS(K23,">0",O23,">0",S23,">0",W23,">0") -> 0
A24: 23 | B24: Brasília de Minas | C24: 3108602 | D24: 0 | E24: 0 | F24: 239.87 | G24: 244.05 | H24: 212.12 | I24: 204.97 | J24: 248.53 | K24: 247.7 | L24: 215.46 | M24: 216.56 | N24: 241.91 | O24: 245.68 | P24: 203.85 | Q24: 199.9 | R24: 244.77 | S24: 234.08 | T24: 192.66 | U24: 191.22 | V24: 246.88 | W24: 247.33 | X24: =COUNTIFS(H24,">0",L24,">0",P24,">0",T24,">0") -> 1 | Y24: =COUNTIFS(I24,">0",M24,">0",Q24,">0",U24,">0") -> 1 | Z24: =COUNTIFS(J24,">0",N24,">0",R24,">0",V24,">0") -> 1 | AA24: =COUNTIFS(K24,">0",O24,">0",S24,">0",W24,">0") -> 1
A25: 24 | B25: Braúnas | C25: 3108800 | D25: #N/A | E25: #N/A | F25: #N/A | G25: #N/A | H25: 196.91 | I25: 213.57 | J25: 0 | K25: 0 | L25: 224.47 | M25: 238.5 | N25: 0 | O25: 0 | P25: #N/A | Q25: #N/A | R25: #N/A | S25: #N/A | T25: 197.6 | U25: 209.42 | V25: 0 | W25: 0 | X25: =COUNTIFS(H25,">0",L25,">0",P25,">0",T25,">0") -> 0 | Y25: =COUNTIFS(I25,">0",M25,">0",Q25,">0",U25,">0") -> 0 | Z25: =COUNTIFS(J25,">0",N25,">0",R25,">0",V25,">0") -> 0 | AA25: =COUNTIFS(K25,">0",O25,">0",S25,">0",W25,">0") -> 0
A26: 25 | B26: Buenópolis | C26: 3109204 | D26: 199.69 | E26: 210.27 | F26: 0 | G26: 0 | H26: 225.22 | I26: 233.17 | J26: 0 | K26: 0 | L26: 200.48 | M26: 210.86 | N26: 0 | O26: 0 | P26: 197.84 | Q26: 198.4 | R26: 0 | S26: 0 | T26: 210.49 | U26: 217.84 | V26: 0 | W26: 0 | X26: =COUNTIFS(H26,">0",L26,">0",P26,">0",T26,">0") -> 1 | Y26: =COUNTIFS(I26,">0",M26,">0",Q26,">0",U26,">0") -> 1 | Z26: =COUNTIFS(J26,">0",N26,">0",R26,">0",V26,">0") -> 0 | AA26: =COUNTIFS(K26,">0",O26,">0",S26,">0",W26,">0") -> 0
A27: 26 | B27: Buritizeiro | C27: 3109402 | D27: 192.66 | E27: 199.82 | F27: 0 | G27: 0 | H27: 199.98 | I27: 204.22 | J27: 0 | K27: 0 | L27: 193.31 | M27: 202.18 | N27: 0 | O27: 0 | P27: 193.59 | Q27: 195.68 | R27: 0 | S27: 0 | T27: 190.89 | U27: 195.3 | V27: 0 | W27: 0 | X27: =COUNTIFS(H27,">0",L27,">0",P27,">0",T27,">0") -> 1 | Y27: =COUNTIFS(I27,">0",M27,">0",Q27,">0",U27,">0") -> 1 | Z27: =COUNTIFS(J27,">0",N27,">0",R27,">0",V27,">0") -> 0 | AA27: =COUNTIFS(K27,">0",O27,">0",S27,">0",W27,">0") -> 0
A28: 27 | B28: Cachoeira de Pajeú | C28: 3102704 | D28: 206.47 | E28: 212.68 | F28: 229.2 | G28: 244.43 | H28: 203.94 | I28: 212.68 | J28: 260.05 | K28: 254.24 | L28: 197.18 | M28: 211.45 | N28: 255.71 | O28: 253.59 | P28: 187.54 | Q28: 192.71 | R28: 246.29 | S28: 238.36 | T28: 198.23 | U28: 208.92 | V28: 0 | W28: 0 | X28: =COUNTIFS(H28,">0",L28,">0",P28,">0",T28,">0") -> 1 | Y28: =COUNTIFS(I28,">0",M28,">0",Q28,">0",U28,">0") -> 1 | Z28: =COUNTIFS(J28,">0",N28,">0",R28,">0",V28,">0") -> 0 | AA28: =COUNTIFS(K28,">0",O28,">0",S28,">0",W28,">0") -> 0
A29: 28 | B29: Campanário | C29: 3110806 | D29: 186.81 | E29: 195.47 | F29: 0 | G29: 0 | H29: 194.43 | I29: 198.4 | J29: 0 | K29: 0 | L29: 198.95 | M29: 212.64 | N29: 0 | O29: 0 | P29: 192.75 | Q29: 201.12 | R29: 0 | S29: 0 | T29: 195 | U29: 197.77 | V29: 0 | W29: 0 | X29: =COUNTIFS(H29,">0",L29,">0",P29,">0",T29,">0") -> 1 | Y29: =COUNTIFS(I29,">0",M29,">0",Q29,">0",U29,">0") -> 1 | Z29: =COUNTIFS(J29,">0",N29,">0",R29,">0",V29,">0") -> 0 | AA29: =COUNTIFS(K29,">0",O29,">0",S29,">0",W29,">0") -> 0
A30: 29 | B30: Campo Azul | C30: 3111150 | D30: 224.93 | E30: 226.04 | F30: 256.07 | G30: 255.08 | H30: 215.61 | I30: 213.34 | J30: 255.29 | K30: 255.99 | L30: 208.78 | M30: 217.16 | N30: 262.34 | O30: 254.84 | P30: 199.26 | Q30: 208.45 | R30: 0 | S30: 0 | T30: 205.25 | U30: 215.89 | V30: 244.95 | W30: 228.95 | X30: =COUNTIFS(H30,">0",L30,">0",P30,">0",T30,">0") -> 1 | Y30: =COUNTIFS(I30,">0",M30,">0",Q30,">0",U30,">0") -> 1 | Z30: =COUNTIFS(J30,">0",N30,">0",R30,">0",V30,">0") -> 0 | AA30: =COUNTIFS(K30,">0",O30,">0",S30,">0",W30,">0") -> 0
A31: 30 | B31: Cantagalo | C31: 3112059 | D31: 211.97 | E31: 220.62 | F31: 0 | G31: 0 | H31: 206.14 | I31: 216.4 | J31: 0 | K31: 0 | L31: 202.36 | M31: 210.26 | N31: 0 | O31: 0 | P31: 213.29 | Q31: 222.43 | R31: 0 | S31: 0 | T31: 193.89 | U31: 219.23 | V31: 0 | W31: 0 | X31: =COUNTIFS(H31,">0",L31,">0",P31,">0",T31,">0") -> 1 | Y31: =COUNTIFS(I31,">0",M31,">0",Q31,">0",U31,">0") -> 1 | Z31: =COUNTIFS(J31,">0",N31,">0",R31,">0",V31,">0") -> 0 | AA31: =COUNTIFS(K31,">0",O31,">0",S31,">0",W31,">0") -> 0
A32: 31 | B32: Capelinha | C32: 3112307 | D32: 223.18 | E32: 253.14 | F32: 0 | G32: 0 | H32: 222.26 | I32: 240.86 | J32: 0 | K32: 0 | L32: 214.19 | M32: 233.47 | N32: 0 | O32: 0 | P32: 204.9 | Q32: 226.72 | R32: 0 | S32: 0 | T32: 223.95 | U32: 243.23 | V32: 0 | W32: 0 | X32: =COUNTIFS(H32,">0",L32,">0",P32,">0",T32,">0") -> 1 | Y32: =COUNTIFS(I32,">0",M32,">0",Q32,">0",U32,">0") -> 1 | Z32: =COUNTIFS(J32,">0",N32,">0",R32,">0",V32,">0") -> 0 | AA32: =COUNTIFS(K32,">0",O32,">0",S32,">0",W32,">0") -> 0
A33: 32 | B33: Capitão Andrade | C33: 3112653 | D33: 202.11 | E33: 217.49 | F33: 0 | G33: 0 | H33: 204.44 | I33: 217.25 | J33: 0 | K33: 0 | L33: 203.93 | M33: 221.84 | N33: 0 | O33: 0 | P33: 192.66 | Q33: 211.46 | R33: 0 | S33: 0 | T33: #N/A | U33: #N/A | V33: #N/A | W33: #N/A | X33: =COUNTIFS(H33,">0",L33,">0",P33,">0",T33,">0") -> 0 | Y33: =COUNTIFS(I33,">0",M33,">0",Q33,">0",U33,">0") -> 0 | Z33: =COUNTIFS(J33,">0",N33,">0",R33,">0",V33,">0") -> 0 | AA33: =COUNTIFS(K33,">0",O33,">0",S33,">0",W33,">0") -> 0
A34: 33 | B34: Capitão Enéas | C34: 3112703 | D34: 173.71 | E34: 182.25 | F34: 203.86 | G34: 215.11 | H34: 176.42 | I34: 183.02 | J34: 213.51 | K34: 206.3 | L34: 170.89 | M34: 180.12 | N34: 0 | O34: 0 | P34: 164.63 | Q34: 182.39 | R34: 0 | S34: 0 | T34: 189.02 | U34: 192.94 | V34: 206.12 | W34: 205.05 | X34: =COUNTIFS(H34,">0",L34,">0",P34,">0",T34,">0") -> 1 | Y34: =COUNTIFS(I34,">0",M34,">0",Q34,">0",U34,">0") -> 1 | Z34: =COUNTIFS(J34,">0",N34,">0",R34,">0",V34,">0") -> 0 | AA34: =COUNTIFS(K34,">0",O34,">0",S34,">0",W34,">0") -> 0
A35: 34 | B35: Caraí | C35: 3113008 | D35: 191.39 | E35: 205.97 | F35: 225.24 | G35: 234.21 | H35: 190.8 | I35: 203.18 | J35: 226.35 | K35: 233.89 | L35: 183.31 | M35: 196.71 | N35: 231.31 | O35: 234.99 | P35: 180.03 | Q35: 183.71 | R35: 221.3 | S35: 226.29 | T35: 184.08 | U35: 190.24 | V35: 241.88 | W35: 234.3 | X35: =COUNTIFS(H35,">0",L35,">0",P35,">0",T35,">0") -> 1 | Y35: =COUNTIFS(I35,">0",M35,">0",Q35,">0",U35,">0") -> 1 | Z35: =COUNTIFS(J35,">0",N35,">0",R35,">0",V35,">0") -> 1 | AA35: =COUNTIFS(K35,">0",O35,">0",S35,">0",W35,">0") -> 1
A36: 35 | B36: Carbonita | C36: 3113503 | D36: #N/A | E36: #N/A | F36: #N/A | G36: #N/A | H36: 209.69 | I36: 217.5 | J36: 213.33 | K36: 217.54 | L36: 223.83 | M36: 227.22 | N36: 239.32 | O36: 252.29 | P36: 206.53 | Q36: 211.73 | R36: 236.11 | S36: 255.77 | T36: 192.29 | U36: 203.19 | V36: 0 | W36: 0 | X36: =COUNTIFS(H36,">0",L36,">0",P36,">0",T36,">0") -> 1 | Y36: =COUNTIFS(I36,">0",M36,">0",Q36,">0",U36,">0") -> 1 | Z36: =COUNTIFS(J36,">0",N36,">0",R36,">0",V36,">0") -> 0 | AA36: =COUNTIFS(K36,">0",O36,">0",S36,">0",W36,">0") -> 0
A37: 36 | B37: Carlos Chagas | C37: 3113701 | D37: 204.39 | E37: 217.38 | F37: 248.11 | G37: 248.1 | H37: 213.78 | I37: 220.81 | J37: 259.12 | K37: 247.48 | L37: 202.51 | M37: 213.23 | N37: 250.12 | O37: 255.8 | P37: 192.74 | Q37: 197.02 | R37: 243.54 | S37: 243.93 | T37: 198.82 | U37: 201.21 | V37: 232.87 | W37: 239.39 | X37: =COUNTIFS(H37,">0",L37,">0",P37,">0",T37,">0") -> 1 | Y37: =COUNTIFS(I37,">0",M37,">0",Q37,">0",U37,">0") -> 1 | Z37: =COUNTIFS(J37,">0",N37,">0",R37,">0",V37,">0") -> 1 | AA37: =COUNTIFS(K37,">0",O37,">0",S37,">0",W37,">0") -> 1
A38: 37 | B38: Carmésia | C38: 3113800 | D38: 207.52 | E38: 210.25 | F38: 279.4 | G38: 273.73 | H38: 200.75 | I38: 207.69 | J38: 263.05 | K38: 267.9 | L38: 224.64 | M38: 240.54 | N38: 254.63 | O38: 270.23 | P38: 197.65 | Q38: 201.99 | R38: 0 | S38: 0 | T38: 203.75 | U38: 219.7 | V38: 262.81 | W38: 261.9 | X38: =COUNTIFS(H38,">0",L38,">0",P38,">0",T38,">0") -> 1 | Y38: =COUNTIFS(I38,">0",M38,">0",Q38,">0",U38,">0") -> 1 | Z38: =COUNTIFS(J38,">0",N38,">0",R38,">0",V38,">0") -> 0 | AA38: =COUNTIFS(K38,">0",O38,">0",S38,">0",W38,">0") -> 0
A39: 38 | B39: Catuji | C39: 3115458 | D39: 195.43 | E39: 210.98 | F39: 0 | G39: 0 | H39: 192.08 | I39: 202.41 | J39: 0 | K39: 0 | L39: 172.89 | M39: 188.62 | N39: 0 | O39: 0 | P39: 175.44 | Q39: 189.06 | R39: 0 | S39: 0 | T39: 189.4 | U39: 194.82 | V39: 0 | W39: 0 | X39: =COUNTIFS(H39,">0",L39,">0",P39,">0",T39,">0") -> 1 | Y39: =COUNTIFS(I39,">0",M39,">0",Q39,">0",U39,">0") -> 1 | Z39: =COUNTIFS(J39,">0",N39,">0",R39,">0",V39,">0") -> 0 | AA39: =COUNTIFS(K39,">0",O39,">0",S39,">0",W39,">0") -> 0
A40: 39 | B40: Catuti | C40: 3115474 | D40: 210.89 | E40: 221.29 | F40: 234.32 | G40: 246.17 | H40: 207.59 | I40: 214.59 | J40: 246.43 | K40: 248.76 | L40: 211.71 | M40: 218.1 | N40: 0 | O40: 0 | P40: 185.75 | Q40: 199.57 | R40: 227 | S40: 234.45 | T40: 206.23 | U40: 220.82 | V40: 269.95 | W40: 257.95 | X40: =COUNTIFS(H40,">0",L40,">0",P40,">0",T40,">0") -> 1 | Y40: =COUNTIFS(I40,">0",M40,">0",Q40,">0",U40,">0") -> 1 | Z40: =COUNTIFS(J40,">0",N40,">0",R40,">0",V40,">0") -> 0 | AA40: =COUNTIFS(K40,">0",O40,">0",S40,">0",W40,">0") -> 0
...

Sheet SAEB
A1: COD_IBGE | B1: NOM_MUN | C1: SAEB17_LP_5 | D1: SAEB17_MT_5 | E1: SAEB19_LP_5 | F1: SAEB19_MT_5 | G1: SAEB21_LP_5 | H1: SAEB21_MT_5 | I1: SAEB23_LP_5 | J1: SAEB23_MT_5
A2: 3101003 | B2: Águas Vermelhas | C2: 213.62 | D2: 219.48 | E2: 224.73 | F2: 238.65 | G2: 189.56 | H2: 196.52 | I2: 205.68 | J2: 214.12
A3: 3101102 | B3: Aimorés | C3: 220.05 | D3: 229.35 | E3: 224.19 | F3: 229.53 | G3: 208.12 | H3: 211.47 | I3: 215.43 | J3: 219.95
A4: 3101706 | B4: Almenara | C4: 192.82 | D4: 195.55 | E4: 190.15 | F4: 200.24 | G4: 191.34 | H4: 199.1 | I4: 195.77 | J4: 204.06
A5: 3101805 | B5: Alpercata | C5: 177.33 | D5: 189.95 | E5: 199.27 | F5: 211.38 | G5: 191.83 | H5: 205.35 | I5: 195.88 | J5: 198.73
A6: 3102852 | B6: Angelândia | C6: 205.97 | D6: 215.57 | E6: 214.58 | F6: 235.89 | G6: 181.85 | H6: 208.94 | I6: 215.01 | J6: 227.73
A7: 3103405 | B7: Araçuaí | C7: 201.51 | D7: 209.14 | E7: 195.62 | F7: 203.67 | G7: 180.92 | H7: 188.92 | I7: 196.17 | J7: 205.92
A8: 3104452 | B8: Aricanduva | C8: 222.21 | D8: 238.95 | E8: 228.01 | F8: 250.16 | G8: 197.66 | H8: 197.69 | I8: 211.63 | J8: 226.58
A9: 3104502 | B9: Arinos | C9: 200.62 | D9: 206.21 | E9: 204.26 | F9: 214.96 | G9: 186.49 | H9: 187.2 | I9: 203 | J9: 203.34
A10: 3104700 | B10: Ataléia | C10: 209.45 | D10: 210.48 | E10: 199.69 | F10: 209.27 | G10: 181.38 | H10: 190.36 | I10: 189.3 | J10: 206.4
A11: 3105202 | B11: Bandeira | C11: 221.48 | D11: 232.52 | E11: 202.24 | F11: 213.17 | G11: 191.48 | H11: 205.92 | I11: 211.02 | J11: 223.46
A12: 3106655 | B12: Berizal | C12: 215.55 | D12: 212.05 | E12: 209.84 | F12: 225.58 | G12: 202.18 | H12: 212.89 | I12: 209.71 | J12: 228.27
A13: 3107307 | B13: Bocaiúva | C13: 200.2 | D13: 211.93 | E13: 197.37 | F13: 207.88 | G13: 189.88 | H13: 204.9 | I13: 190.3 | J13: 203.13
... A189: 3171907 | B189: Virgolândia | C189: 221 | D189: 233.34 | E189: 200.75 | F189: 214.49 | G189: 196.58 | H189: 198.09 | I189: 222.66 | J189: 224.88

Sheet GASTO_original
A1: COD_ENTE | B1: COD_IBGE | C1: NOM_MUN | D1: NUM_ANO | E1: SIOPE_NOM | F1: SIOPE_CORR | G1: SICONFI_NOM | H1: SICONFI_CORR | I1: ENTRA?
A2: 310050 | B2: 3100500 | C2: Açucena | D2: 2015 | E2: 7887.93 | F2: 3415.39 | G2: 8869.01 | H2: 3840.19 | I2: =IFERROR(VLOOKUP(B2,SAEB!A:A,1,0),0) -> 0
A3: 310050 | B3: 3100500 | C3: Açucena | D3: 2016 | E3: 6016.98 | F3: 4419.47 | G3: 9094.65 | H3: 6680.01 | I3: =IFERROR(VLOOKUP(B3,SAEB!A:A,1,0),0) -> 0
A4: 310050 | B4: 3100500 | C4: Açucena | D4: 2017 | E4: 7254.09 | F4: 11360.64 | G4: 11384.06 | H4: 17828.59 | I4: =IFERROR(VLOOKUP(B4,SAEB!A:A,1,0),0) -> 0
A5: 310050 | B5: 3100500 | C5: Açucena | D5: 2018 | E5: 6719.32 | F5: 8278.2 | G5: 11509.4 | H5: 14179.58 | I5: =IFERROR(VLOOKUP(B5,SAEB!A:A,1,0),0) -> 0
A6: 310050 | B6: 3100500 | C6: Açucena | D6: 2019 | E6: 7898.7 | F6: 8466.82 | G6: 14124.33 | H6: 15140.23 | I6: =IFERROR(VLOOKUP(B6,SAEB!A:A,1,0),0) -> 0
A7: 310050 | B7: 3100500 | C7: Açucena | D7: 2020 | E7: 8873.14 | F7: 9069.45 | G7: 11211.79 | H7: 11459.83 | I7: =IFERROR(VLOOKUP(B7,SAEB!A:A,1,0),0) -> 0
A8: 310050 | B8: 3100500 | C8: Açucena | D8: 2021 | E8: 13872.98 | F8: 6371.09 | G8: 15418.73 | H8: 7080.97 | I8: =IFERROR(VLOOKUP(B8,SAEB!A:A,1,0),0) -> 0
A9: 310050 | B9: 3100500 | C9: Açucena | D9: 2022 | E9: 16014.08 | F9: 12778.07 | G9: 26819.15 | H9: 21399.73 | I9: =IFERROR(VLOOKUP(B9,SAEB!A:A,1,0),0) -> 0
A10: 310050 | B10: 3100500 | C10: Açucena | D10: 2023 | E10: 17396.47 | F10: 17396.47 | G10: 33334.2 | H10: 33334.2 | I10: =IFERROR(VLOOKUP(B10,SAEB!A:A,1,0),0) -> 0
A11: 310050 | B11: 3100500 | C11: Açucena | D11: 2024 | E11: 19411.56 | F11: 18567.58 | G11: 25923.54 | H11: 24796.43 | I11: =IFERROR(VLOOKUP(B11,SAEB!A:A,1,0),0) -> 0
A12: 310060 | B12: 3100609 | C12: Água Boa | D12: 2015 | E12: 15155.36 | F12: 6562.11 | G12: 15157.79 | H12: 6563.16 | I12: =IFERROR(VLOOKUP(B12,SAEB!A:A,1,0),0) -> 0
A13: 310060 | B13: 3100609 | C13: Água Boa | D13: 2016 | E13: 11097.28 | F13: 8150.94 | G13: 17499.54 | H13: 12853.4 | I13: =IFERROR(VLOOKUP(B13,SAEB!A:A,1,0),0) -> 0
... A128: 310450 | B128: 3104502 | C128: Arinos | D128: 2021 | E128: 9804.46 | F128: 4502.64 | G128: 8963.67 | H128: 4116.52 | I128: =IFERROR(VLOOKUP(B128,SAEB!A:A,1,0),0) -> 3104502
A129: 310450 | B129: 3104502 | C129: Arinos | D129: 2022 | E129: 16453.15 | F129: 13128.42 | G129: #N/A | H129: #N/A | I129: =IFERROR(VLOOKUP(B129,SAEB!A:A,1,0),0) -> 3104502
A130: 310450 | B130: 3104502 | C130: Arinos | D130: 2023 | E130: 18313.72 | F130: 18313.72 | G130: 23443.17 | H130: 23443.17 | I130: =IFERROR(VLOOKUP(B130,SAEB!A:A,1,0),0) -> 3104502
A131: 310450 | B131: 3104502 | C131: Arinos | D131: 2024 | E131: 19718.54 | F131: 18861.21 | G131: 24937.44 | H131: 23853.2 | I131: =IFERROR(VLOOKUP(B131,SAEB!A:A,1,0),0) -> 3104502
A132: 310470 | B132: 3104700 | C132: Ataléia | D132: 2015 | E132: 7240.53 | F132: 3135.07 | G132: 9064.47 | H132: 3924.82 | I132: =IFERROR(VLOOKUP(B132,SAEB!A:A,1,0),0) -> 3104700
A133: 310470 | B133: 3104700 | C133: Ataléia | D133: 2016 | E133: 10166.3 | F133: 7467.14 | G133: 12353.36 | H133: 9073.54 | I133: =IFERROR(VLOOKUP(B133,SAEB!A:A,1,0),0) -> 3104700
A134: 310470 | B134: 3104700 | C134: Ataléia | D134: 2017 | E134: 9947.96 | F134: 15579.52 | G134: 12845.73 | H134: 20117.71 | I134: =IFERROR(VLOOKUP(B134,SAEB!A:A,1,0),0) -> 3104700
A135: 310470 | B135: 3104700 | C135: Ataléia | D135: 2018 | E135: 12567.65 | F135: 15483.34 | G135: 11754.39 | H135: 14481.41 | I135: =IFERROR(VLOOKUP(B135,SAEB!A:A,1,0),0) -> 3104700
A136: 310470 | B136: 3104700 | C136: Ataléia | D136: 2019 | E136: 10714.64 | F136: 11485.3 | G136: 12441.86 | H136: 13336.75 | I136: =IFERROR(VLOOKUP(B136,SAEB!A:A,1,0),0) -> 3104700
A137: 310470 | B137: 3104700 | C137: Ataléia | D137: 2020 | E137: 12851.98 | F137: 13136.32 | G137: 11106.47 | H137: 11352.18 | I137: =IFERROR(VLOOKUP(B137,SAEB!A:A,1,0),0) -> 3104700
A138: 310470 | B138: 3104700 | C138: Ataléia | D138: 2021 | E138: 10120.36 | F138: 4647.72 | G138: 8862.68 | H138: 4070.14 | I138: =IFERROR(VLOOKUP(B138,SAEB!A:A,1,0),0) -> 3104700
A139: 310470 | B139: 3104700 | C139: Ataléia | D139: 2022 | E139: 12792.76 | F139: 10207.69 | G139: 14370.42 | H139: 11466.55 | I139: =IFERROR(VLOOKUP(B139,SAEB!A:A,1,0),0) -> 3104700
A140: 310470 | B140: 3104700 | C140: Ataléia | D140: 2023 | E140: 14593.83 | F140: 14593.83 | G140: 17720.62 | H140: 17720.62 | I140: =IFERROR(VLOOKUP(B140,SAEB!A:A,1,0),0) -> 3104700
A141: 310470 | B141: 3104700 | C141: Ataléia | D141: 2024 | E141: 15763.11 | F141: 15077.76 | G141: 22675.38 | H141: 21689.49 | I141: =IFERROR(VLOOKUP(B141,SAEB!A:A,1,0),0) -> 3104700
... A243: 310880 | B243: 3108800 | C243: Braúnas | D243: 2016 | E243: 6462.41 | F243: 4746.64 | G243: 10940.94 | H243: 8036.11 | I243: =IFERROR(VLOOKUP(B243,SAEB!A:A,1,0),0) -> 0
A244: 310880 | B244: 3108800 | C244: Braúnas | D244: 2017 | E244: 7710.81 | F244: 12075.91 | G244: #N/A | H244: #N/A | I244: =IFERROR(VLOOKUP(B244,SAEB!A:A,1,0),0) -> 0
A245: 310880 | B245: 3108800 | C245: Braúnas | D245: 2018 | E245: 8843.79 | F245: 10895.55 | G245: 12572.67 | H245: 15489.53 | I245: =IFERROR(VLOOKUP(B245,SAEB!A:A,1,0),0) -> 0
A246: 310880 | B246: 3108800 | C246: Braúnas | D246: 2019 | E246: 9133.49 | F246: 9790.42 | G246: 12286.96 | H246: 13170.71 | I246: =IFERROR(VLOOKUP(B246,SAEB!A:A,1,0),0) -> 0
A247: 310880 | B247: 3108800 | C247: Braúnas | D247: 2020 | E247: 9850.43 | F247: 10068.36 | G247: 11118.48 | H247: 11364.46 | I247: =IFERROR(VLOOKUP(B247,SAEB!A:A,1,0),0) -> 0
A248: 310880 | B248: 3108800 | C248: Braúnas | D248: 2021 | E248: 11914.29 | F248: 5471.57 | G248: 15530.14 | H248: 7132.13 | I248: =IFERROR(VLOOKUP(B248,SAEB!A:A,1,0),0) -> 0
A249: 310880 | B249: 3108800 | C249: Braúnas | D249: 2022 | E249: 17907.71 | F249: 14289.05 | G249: 31219.9 | H249: 24911.22 | I249: =IFERROR(VLOOKUP(B249,SAEB!A:A,1,0),0) -> 0
A250: 310880 | B250: 3108800 | C250: Braúnas | D250: 2023 | E250: 14943 | F250: 14943 | G250: 30387.99 | H250: 30387.99 | I250: =IFERROR(VLOOKUP(B250,SAEB!A:A,1,0),0) -> 0
A251: 310880 | B251: 3108800 | C251: Braúnas | D251: 2024 | E251: 19405.8 | F251: 18562.07 | G251: 34035.6 | H251: 32555.79 | I251: =IFERROR(VLOOKUP(B251,SAEB!A:A,1,0),0) -> 0
A252: 310920 | B252: 3109204 | C252: Buenópolis | D252: 2015 | E252: 5771.39 | F252: 2498.95 | G252: 5731.74 | H252: 2481.78 | I252: =IFERROR(VLOOKUP(B252,SAEB!A:A,1,0),0) -> 3109204
A253: 310920 | B253: 3109204 | C253: Buenópolis | D253: 2016 | E253: 6040.11 | F253: 4436.46 | G253: 5933.24 | H253: 4357.96 | I253: =IFERROR(VLOOKUP(B253,SAEB!A:A,1,0),0) -> 3109204
A254: 310920 | B254: 3109204 | C254: Buenópolis | D254: 2017 | E254: 6519.79 | F254: 10210.65 | G254: 6878.21 | H254: 10771.98 | I254: =IFERROR(VLOOKUP(B254,SAEB!A:A,1,0),0) -> 3109204
A255: 310920 | B255: 3109204 | C255: Buenópolis | D255: 2018 | E255: 6359.48 | F255: 7834.88 | G255: 6999.62 | H255: 8623.53 | I255: =IFERROR(VLOOKUP(B255,SAEB!A:A,1,0),0) -> 3109204
...

Sheet GASTO
A1: COD_ENTE | B1: COD_IBGE | C1: NOM_MUN | D1: NUM_ANO | E1: SIOPE_NOM | F1: SIOPE_CORR | G1: SICONFI_NOM | H1: SICONFI_CORR
A2: 310100 | B2: 3101003 | C2: Águas Vermelhas | D2: 2015 | E2: 7437.25 | F2: 11211.35 | G2: 6309.96 | H2: 9512.0125
A3: 310100 | B3: 3101003 | C3: Águas Vermelhas | D3: 2016 | E3: 7762.69 | F3: 11009.652 | G3: 9434.29 | H3: 13380.443
A4: 310100 | B4: 3101003 | C4: Águas Vermelhas | D4: 2017 | E4: 7678.3 | F4: 10578.18 | G4: 9783.25 | H4: 13478.113
A5: 310100 | B5: 3101003 | C5: Águas Vermelhas | D5: 2018 | E5: 9331.74 | F5: 12391.929 | G5: 10470.37 | H5: 13903.948
A6: 310100 | B6: 3101003 | C6: Águas Vermelhas | D6: 2019 | E6: 8769.95 | F6: 11165.122 | G6: 12178.48 | H6: 15504.562
A7: 310100 | B7: 3101003 | C7: Águas Vermelhas | D7: 2020 | E7: 9709.96 | F7: 11827.554 | G7: 8622.01 | H7: 10502.338
A8: 310100 | B8: 3101003 | C8: Águas Vermelhas | D8: 2021 | E8: 9960.77 | F8: 11023.945 | G8: 7249.96 | H8: 8023.7951
A9: 310100 | B9: 3101003 | C9: Águas Vermelhas | D9: 2022 | E9: 12979.18 | F9: 13578.973 | G9: 14113.27 | H9: 14765.471
A10: 310100 | B10: 3101003 | C10: Águas Vermelhas | D10: 2023 | E10: 14605.44 | F10: 14605.44 | G10: 19737.56 | H10: 19737.564
A11: 310100 | B11: 3101003 | C11: Águas Vermelhas | D11: 2024 | E11: 12322.2 | F11: 11754.325 | G11: 13900.33 | H11: 13259.722
A12: 310110 | B12: 3101102 | C12: Aimorés | D12: 2015 | E12: 5163.57 | F12: 7783.8706 | G12: 5042.91 | H12: 7601.9835
A13: 310110 | B13: 3101102 | C13: Aimorés | D13: 2016 | E13: 6444.05 | F13: 9139.454 | G13: 6853.61 | H13: 9720.3219
... A1881: 317190 | B1881: 3171907 | C1881: Virgolândia | D1881: 2024 | E1881: 17609.32 | F1881: 16797.786 | G1881: 21131.5 | H1881: 20157.646

Sheet SICONFI
A1: KEY | B1: ano_exercicio | C1: id_ente | D1: ente | E1: CTef | F1: QTD_est | G1: Custo_est_nom | H1: Custo_est_corr
A2: =B2&C2 -> 20153100500 | B2: 2015 | C2: 3100500 | D2: Açucena | E2: 4611887.5 | F2: =VLOOKUP(B2&C2,CENSO!A:G,7,0) -> 520 | G2: =E2/F2 -> 8869.0144 | H2: =G2*(IPCA!$B$10/VLOOKUP(B2,IPCA!A:B,2,0)) -> 13369.676
A3: =B3&C3 -> 20153100609 | B3: 2015 | C3: 3100609 | D3: Água Boa | E3: 4729229 | F3: =VLOOKUP(B3&C3,CENSO!A:G,7,0) -> 312 | G3: =E3/F3 -> 15157.785 | H3: =G3*(IPCA!$B$10/VLOOKUP(B3,IPCA!A:B,2,0)) -> 22849.741
A4: =B4&C4 -> 20153100906 | B4: 2015 | C4: 3100906 | D4: Águas Formosas | E4: 4347332 | F4: =VLOOKUP(B4&C4,CENSO!A:G,7,0) -> 415 | G4: =E4/F4 -> 10475.499 | H4: =G4*(IPCA!$B$10/VLOOKUP(B4,IPCA!A:B,2,0)) -> 15791.386
A5: =B5&C5 -> 20153101003 | B5: 2015 | C5: 3101003 | D5: Águas Vermelhas | E5: 2763764.2 | F5: =VLOOKUP(B5&C5,CENSO!A:G,7,0) -> 438 | G5: =E5/F5 -> 6309.9639 | H5: =G5*(IPCA!$B$10/VLOOKUP(B5,IPCA!A:B,2,0)) -> 9512.0125
A6: =B6&C6 -> 20153101102 | B6: 2015 | C6: 3101102 | D6: Aimorés | E6: 6626386.3 | F6: =VLOOKUP(B6&C6,CENSO!A:G,7,0) -> 1314 | G6: =E6/F6 -> 5042.9119 | H6: =G6*(IPCA!$B$10/VLOOKUP(B6,IPCA!A:B,2,0)) -> 7601.9835
A7: =B7&C7 -> 20153101706 | B7: 2015 | C7: 3101706 | D7: Almenara | E7: 14645710 | F7: =VLOOKUP(B7&C7,CENSO!A:G,7,0) -> 4079 | G7: =E7/F7 -> 3590.5149 | H7: =G7*(IPCA!$B$10/VLOOKUP(B7,IPCA!A:B,2,0)) -> 5412.5544
A8: =B8&C8 -> 20153101805 | B8: 2015 | C8: 3101805 | D8: Alpercata | E8: 4082299.2 | F8: =VLOOKUP(B8&C8,CENSO!A:G,7,0) -> 765 | G8: =E8/F8 -> 5336.3388 | H8: =G8*(IPCA!$B$10/VLOOKUP(B8,IPCA!A:B,2,0)) -> 8044.3124
A9: =B9&C9 -> 20153102209 | B9: 2015 | C9: 3102209 | D9: Alvarenga | E9: 1405547.1 | F9: =VLOOKUP(B9&C9,CENSO!A:G,7,0) -> 197 | G9: =E9/F9 -> 7134.7569 | H9: =G9*(IPCA!$B$10/VLOOKUP(B9,IPCA!A:B,2,0)) -> 10755.354
A10: =B10&C10 -> 20153102852 | B10: 2015 | C10: 3102852 | D10: Angelândia | E10: 4355671.9 | F10: =VLOOKUP(B10&C10,CENSO!A:G,7,0) -> 554 | G10: =E10/F10 -> 7862.2236 | H10: =G10*(IPCA!$B$10/VLOOKUP(B10,IPCA!A:B,2,0)) -> 11851.98
A11: =B11&C11 -> 20153103405 | B11: 2015 | C11: 3103405 | D11: Araçuaí | E11: 6045982.8 | F11: =VLOOKUP(B11&C11,CENSO!A:G,7,0) -> 1197 | G11: =E11/F11 -> 5050.9464 | H11: =G11*(IPCA!$B$10/VLOOKUP(B11,IPCA!A:B,2,0)) -> 7614.0951
A12: =B12&C12 -> 20153104452 | B12: 2015 | C12: 3104452 | D12: Aricanduva | E12: 2470841.8 | F12: =VLOOKUP(B12&C12,CENSO!A:G,7,0) -> 277 | G12: =E12/F12 -> 8920.0066 | H12: =G12*(IPCA!$B$10/VLOOKUP(B12,IPCA!A:B,2,0)) -> 13446.545
A13: =B13&C13 -> 20153104502 | B13: 2015 | C13: 3104502 | D13: Arinos | E13: 10781053 | F13: =VLOOKUP(B13&C13,CENSO!A:G,7,0) -> 1155 | G13: =E13/F13 -> 9334.2454 | H13: =G13*(IPCA!$B$10/VLOOKUP(B13,IPCA!A:B,2,0)) -> 14070.993
... A2643: =B2643&C2643 -> 20213166709 | B2643: 2021 | C2643: 3166709 | D2643: Serra dos Aimorés | E2643: 3912631.4 | F2643: =VLOOKUP(B2643&C2643,CENSO!A:G,7,0) -> 327 | G2643: =E2643/F2643 -> 11965.234 | H2643: =G2643*(IPCA!$B$10/VLOOKUP(B2643,IPCA!A:B,2,0)) -> 13242.358

Sheet SICONFI_calc
A1: ano_exercicio | B1: id_ente | C1: ente | D1: coluna | E1: conta | F1: valor | G1: CDT | H1: Pef | I1: CIadm | J1: CTef
A2: 2015 | B2: 3100500 | C2: Açucena | D2: Despesas Liquidadas | E2: 12 - Educação | F2: 5403110.8 | G2: 4840933 | H2: 0.95268567 | I2: 0 | J2: 0
A3: 2015 | B3: 3100500 | C3: Açucena | D3: Despesas Liquidadas | E3: 12.361 - Ensino Fundamental | F3: 4611887.5 | I3: 0 | J3: 4611887.5
A4: 2015 | B4: 3100500 | C4: Açucena | D4: Despesas Liquidadas | E4: 12.365 - Educação Infantil | F4: 229045.48 | I4: 0 | J4: 0
A5: 2015 | B5: 3100500 | C5: Açucena | D5: Despesas Liquidadas | E5: 12.999 - Demais Subfunções Educação | F5: 562177.87 | I5: 0 | J5: 0
A6: 2015 | B6: 3100609 | C6: Água Boa | D6: Despesas Liquidadas | E6: 12 - Educação | F6: 6748007.2 | G6: 6107425.6 | H6: 0.77434082 | I6: 0 | J6: 0
A7: 2015 | B7: 3100609 | C7: Água Boa | D7: Despesas Liquidadas | E7: 12.361 - Ensino Fundamental | F7: 4729229 | I7: 0 | J7: 4729229
A8: 2015 | B8: 3100609 | C8: Água Boa | D8: Despesas Liquidadas | E8: 12.365 - Educação Infantil | F8: 1341622.6 | I8: 0 | J8: 0
A9: 2015 | B9: 3100609 | C9: Água Boa | D9: Despesas Liquidadas | E9: 12.366 - Educação de Jovens e Adultos | F9: 17666.81 | I9: 0 | J9: 0
A10: 2015 | B10: 3100609 | C10: Água Boa | D10: Despesas Liquidadas | E10: 12.367 - Educação Especial | F10: 18907.27 | I10: 0 | J10: 0
A11: 2015 | B11: 3100609 | C11: Água Boa | D11: Despesas Liquidadas | E11: 12.999 - Demais Subfunções Educação | F11: 640581.65 | I11: 0 | J11: 0
A12: 2015 | B12: 3100906 | C12: Águas Formosas | D12: Despesas Liquidadas | E12: 12 - Educação | F12: 7753781.6 | G12: 6700546.6 | H12: 0.64880259 | I12: 0 | J12: 0
A13: 2015 | B13: 3100906 | C13: Águas Formosas | D13: Despesas Liquidadas | E13: 12.361 - Ensino Fundamental | F13: 4347332 | I13: 0 | J13: 4347332
A14: 2015 | B14: 3100906 | C14: Águas Formosas | D14: Despesas Liquidadas | E14: 12.364 - Ensino Superior | F14: 30751.05 | I14: 0 | J14: 0
A15: 2015 | B15: 3100906 | C15: Águas Formosas | D15: Despesas Liquidadas | E15: 12.365 - Educação Infantil | F15: 2292463.6 | I15: 0 | J15: 0
A16: 2015 | B16: 3100906 | C16: Águas Formosas | D16: Despesas Liquidadas | E16: 12.367 - Educação Especial | F16: 30000 | I16: 0 | J16: 0
A17: 2015 | B17: 3100906 | C17: Águas Formosas | D17: Despesas Liquidadas | E17: 12.999 - Demais Subfunções Educação | F17: 1053235 | I17: 0 | J17: 0
A18: 2015 | B18: 3101003 | C18: Águas Vermelhas | D18: Despesas Liquidadas | E18: 12 - Educação | F18: 4554690.3 | G18: 3428667.4 | H18: 0.80607532 | I18: 0 | J18: 0
A19: 2015 | B19: 3101003 | C19: Águas Vermelhas | D19: Despesas Liquidadas | E19: 12.361 - Ensino Fundamental | F19: 2763764.2 | I19: 0 | J19: 2763764.2
A20: 2015 | B20: 3101003 | C20: Águas Vermelhas | D20: Despesas Liquidadas | E20: 12.364 - Ensino Superior | F20: 9000 | I20: 0 | J20: 0
A21: 2015 | B21: 3101003 | C21: Águas Vermelhas | D21: Despesas Liquidadas | E21: 12.365 - Educação Infantil | F21: 654811.71 | I21: 0 | J21: 0
A22: 2015 | B22: 3101003 | C22: Águas Vermelhas | D22: Despesas Liquidadas | E22: 12.366 - Educação de Jovens e Adultos | F22: 1091.5 | I22: 0 | J22: 0
A23: 2015 | B23: 3101003 | C23: Águas Vermelhas | D23: Despesas Liquidadas | E23: 12.999 - Demais Subfunções Educação | F23: 1126022.9 | I23: 0 | J23: 0
A24: 2015 | B24: 3101102 | C24: Aimorés | D24: Despesas Liquidadas | E24: 12 - Educação | F24: 10212591 | G24: 6991141.9 | H24: 0.94782603 | I24: 0 | J24: 0
A25: 2015 | B25: 3101102 | C25: Aimorés | D25: Despesas Liquidadas | E25: 12.361 - Ensino Fundamental | F25: 6626386.3 | I25: 0 | J25: 6626386.3
A26: 2015 | B26: 3101102 | C26: Aimorés | D26: Despesas Liquidadas | E26: 12.364 - Ensino Superior | F26: 158502.01 | I26: 0 | J26: 0
A27: 2015 | B27: 3101102 | C27: Aimorés | D27: Despesas Liquidadas | E27: 12.365 - Educação Infantil | F27: 203493.84 | I27: 0 | J27: 0
A28: 2015 | B28: 3101102 | C28: Aimorés | D28: Despesas Liquidadas | E28: 12.367 - Educação Especial | F28: 2759.8 | I28: 0 | J28: 0
A29: 2015 | B29: 3101102 | C29: Aimorés | D29: Despesas Liquidadas | E29: 12.999 - Demais Subfunções Educação | F29: 3221449.3 | I29: 0 | J29: 0
A30: 2015 | B30: 3101706 | C30: Almenara | D30: Despesas Liquidadas | E30: 12 - Educação | F30: 23065392 | G30: 17486903 | H30: 0.83752456 | I30: 0 | J30: 0
A31: 2015 | B31: 3101706 | C31: Almenara | D31: Despesas Liquidadas | E31: 12.361 - Ensino Fundamental | F31: 14645710 | I31: 0 | J31: 14645710
A32: 2015 | B32: 3101706 | C32: Almenara | D32: Despesas Liquidadas | E32: 12.364 - Ensino Superior | F32: 67098.44 | I32: 0 | J32: 0
A33: 2015 | B33: 3101706 | C33: Almenara | D33: Despesas Liquidadas | E33: 12.365 - Educação Infantil | F33: 2774093.8 | I33: 0 | J33: 0
A34: 2015 | B34: 3101706 | C34: Almenara | D34: Despesas Liquidadas | E34: 12.999 - Demais Subfunções Educação | F34: 5578488.9 | I34: 0 | J34: 0
A35: 2015 | B35: 3101805 | C35: Alpercata | D35: Despesas Liquidadas | E35: 12 - Educação | F35: 5636362.7 | G35: 4459946.6 | H35: 0.91532467 | I35: 0 | J35: 0
A36: 2015 | B36: 3101805 | C36: Alpercata | D36: Despesas Liquidadas | E36: 12.361 - Ensino Fundamental | F36: 4082299.2 | I36: 0 | J36: 4082299.2
A37: 2015 | B37: 3101805 | C37: Alpercata | D37: Despesas Liquidadas | E37: 12.365 - Educação Infantil | F37: 377647.45 | I37: 0 | J37: 0
A38: 2015 | B38: 3101805 | C38: Alpercata | D38: Despesas Liquidadas | E38: 12.999 - Demais Subfunções Educação | F38: 1176416.1 | I38: 0 | J38: 0
A39: 2015 | B39: 3102209 | C39: Alvarenga | D39: Despesas Liquidadas | E39: 12 - Educação | F39: 2056646.8 | G39: 1432953.7 | H39: 0.98087407 | I39: 0 | J39: 0
A40: 2015 | B40: 3102209 | C40: Alvarenga | D40: Despesas Liquidadas | E40: 12.361 - Ensino Fundamental | F40: 1405547.1 | I40: 0 | J40: 1405547.1
...

Sheet INSE
A1: NU_ANO_SAEB | B1: CO_MUNICIPIO | C1: NO_MUNICIPIO | D1: MD_INSE_2019 | E1: MD_INSE_2021 | F1: MD_INSE_2023
A2: 2023 | B2: 3137007 | C2: Ladainha | D2: 3.922 | E2: 3.98 | F2: 4.6678
A3: 2023 | B3: 3136959 | C3: Juvenília | D3: 4.0868 | E3: 4.02 | F3: 4.3757
A4: 2023 | B4: 3136801 | C4: Juramento | D4: 4.639 | E4: 4.64 | F4: 4.6037
A5: 2023 | B5: 3136553 | C5: José Raydan | D5: 4.6672 | E5: 4.52 | F5: 4.8764
A6: 2023 | B6: 3136405 | C6: Joaquim Felício | D6: 4.5982 | E6: 4.85 | F6: 4.6604
A7: 2023 | B7: 3136009 | C7: Joaíma | D7: 4.2055 | E7: 4.36 | F7: 4.4576
A8: 2023 | B8: 3135803 | C8: Jequitinhonha | D8: 4.1399 | E8: 4.15 | F8: 4.3474
A9: 2023 | B9: 3135357 | C9: Japonvar | D9: 4.4538 | E9: 4.3 | F9: 4.5505
A10: 2023 | B10: 3135209 | C10: Januária | D10: 4.1958 | E10: 4.47 | F10: 4.1741
A11: 2023 | B11: 3135100 | C11: Janaúba | D11: 4.3945 | E11: 4.56 | F11: 4.6463
A12: 2023 | B12: 3135050 | C12: Jaíba | D12: 4.3168 | E12: 4.56 | F12: 4.6303
A13: 2023 | B13: 3134707 | C13: Jacinto | D13: 4.4632 | E13: 4.44 | F13: 4.5792
... A189: 2023 | B189: 3171907 | C189: Virgolândia | D189: 4.5768 | E189: 4.56 | F189: 4.7649

Sheet CENSO
A1: KEY | B1: ID | C1: NOM_MUN | D1: ANO | E1: ANOS INICIAIS | F1: ANOS FINAIS | G1: TOTAL
A2: =D2&B2 -> 20153100500 | B2: 3100500 | C2: Açucena | D2: 2015 | E2: 298 | F2: 222 | G2: =SUM(E2:F2) -> 520
A3: =D3&B3 -> 20153100609 | B3: 3100609 | C3: Água Boa | D3: 2015 | E3: 312 | F3: 0 | G3: =SUM(E3:F3) -> 312
A4: =D4&B4 -> 20153100906 | B4: 3100906 | C4: Águas Formosas | D4: 2015 | E4: 246 | F4: 169 | G4: =SUM(E4:F4) -> 415
A5: =D5&B5 -> 20153101003 | B5: 3101003 | C5: Águas Vermelhas | D5: 2015 | E5: 438 | F5: 0 | G5: =SUM(E5:F5) -> 438
A6: =D6&B6 -> 20153101102 | B6: 3101102 | C6: Aimorés | D6: 2015 | E6: 855 | F6: 459 | G6: =SUM(E6:F6) -> 1314
A7: =D7&B7 -> 20153101706 | B7: 3101706 | C7: Almenara | D7: 2015 | E7: 3042 | F7: 1037 | G7: =SUM(E7:F7) -> 4079
A8: =D8&B8 -> 20153101805 | B8: 3101805 | C8: Alpercata | D8: 2015 | E8: 534 | F8: 231 | G8: =SUM(E8:F8) -> 765
A9: =D9&B9 -> 20153102209 | B9: 3102209 | C9: Alvarenga | D9: 2015 | E9: 197 | F9: 0 | G9: =SUM(E9:F9) -> 197
A10: =D10&B10 -> 20153102852 | B10: 3102852 | C10: Angelândia | D10: 2015 | E10: 554 | F10: 0 | G10: =SUM(E10:F10) -> 554
A11: =D11&B11 -> 20153103405 | B11: 3103405 | C11: Araçuaí | D11: 2015 | E11: 796 | F11: 401 | G11: =SUM(E11:F11) -> 1197
A12: =D12&B12 -> 20153104452 | B12: 3104452 | C12: Aricanduva | D12: 2015 | E12: 277 | F12: 0 | G12: =SUM(E12:F12) -> 277
A13: =D13&B13 -> 20153104502 | B13: 3104502 | C13: Arinos | D13: 2015 | E13: 889 | F13: 266 | G13: =SUM(E13:F13) -> 1155
... A2651: =D2651&B2651 -> 20243171907 | B2651: 3171907 | C2651: Virgolândia | D2651: 2024 | E2651: 216 | F2651: 0 | G2651: =SUM(E2651:F2651) -> 216

Sheet MATRÍCULAS
A1: codigo_ibge | B1: NOM_MUNIC | C1: ano | D1: matriculas_anos_iniciais_urbana | E1: matriculas_anos_finais_urbana | F1: matriculas_anos_iniciais_rural | G1: matriculas_anos_finais_rural
A2: 3101003 | B2: =VLOOKUP(A2,[1]SAEB!$A:$B,2,0) -> Águas Vermelhas | C2: 2015 | D2: 358 | E2: 0 | F2: 80 | G2: 0
A3: 3101102 | B3: =VLOOKUP(A3,[1]SAEB!$A:$B,2,0) -> Aimorés | C3: 2015 | D3: 765 | E3: 459 | F3: 90 | G3: 0
A4: 3101706 | B4: =VLOOKUP(A4,[1]SAEB!$A:$B,2,0) -> Almenara | C4: 2015 | D4: 2445 | E4: 725 | F4: 597 | G4: 312
A5: 3101805 | B5: =VLOOKUP(A5,[1]SAEB!$A:$B,2,0) -> Alpercata | C5: 2015 | D5: 451 | E5: 231 | F5: 83 | G5: 0
A6: 3102852 | B6: =VLOOKUP(A6,[1]SAEB!$A:$B,2,0) -> Angelândia | C6: 2015 | F6: 554 | G6: 0
A7: 3103405 | B7: =VLOOKUP(A7,[1]SAEB!$A:$B,2,0) -> Araçuaí | C7: 2015 | D7: 314 | E7: 0 | F7: 482 | G7: 401
A8: 3104452 | B8: =VLOOKUP(A8,[1]SAEB!$A:$B,2,0) -> Aricanduva | C8: 2015 | D8: 211 | E8: 0 | F8: 66 | G8: 0
A9: 3104502 | B9: =VLOOKUP(A9,[1]SAEB!$A:$B,2,0) -> Arinos | C9: 2015 | D9: 448 | E9: 0 | F9: 441 | G9: 266
A10: 3104700 | B10: =VLOOKUP(A10,[1]SAEB!$A:$B,2,0) -> Ataléia | C10: 2015 | D10: 221 | E10: 60 | F10: 253 | G10: 0
A11: 3105202 | B11: =VLOOKUP(A11,[1]SAEB!$A:$B,2,0) -> Bandeira | C11: 2015 | D11: 0 | E11: 0 | F11: 358 | G11: 73
A12: 3106655 | B12: =VLOOKUP(A12,[1]SAEB!$A:$B,2,0) -> Berizal | C12: 2015 | D12: 249 | E12: 0 | F12: 29 | G12: 0
A13: 3107307 | B13: =VLOOKUP(A13,[1]SAEB!$A:$B,2,0) -> Bocaiúva | C13: 2015 | D13: 572 | E13: 472 | F13: 387 | G13: 235
A14: 3108206 | B14: =VLOOKUP(A14,[1]SAEB!$A:$B,2,0) -> Bonfinópolis de Minas | C14: 2015 | D14: 268 | E14: 208 | F14: 30 | G14: 0
A15: 3108602 | B15: =VLOOKUP(A15,[1]SAEB!$A:$B,2,0) -> Brasília de Minas | C15: 2015 | D15: 0 | E15: 186 | F15: 426 | G15: 250
A16: 3109204 | B16: =VLOOKUP(A16,[1]SAEB!$A:$B,2,0) -> Buenópolis | C16: 2015 | D16: 548 | E16: 0 | F16: 64 | G16: 0
A17: 3109402 | B17: =VLOOKUP(A17,[1]SAEB!$A:$B,2,0) -> Buritizeiro | C17: 2015 | D17: 987 | E17: 0 | F17: 196 | G17: 0
A18: 3102704 | B18: =VLOOKUP(A18,[1]SAEB!$A:$B,2,0) -> Cachoeira de Pajeú | C18: 2015 | D18: 296 | E18: 0 | F18: 411 | G18: 157
A19: 3110806 | B19: =VLOOKUP(A19,[1]SAEB!$A:$B,2,0) -> Campanário | C19: 2015 | D19: 296 | E19: 0
A20: 3111150 | B20: =VLOOKUP(A20,[1]SAEB!$A:$B,2,0) -> Campo Azul | C20: 2015 | D20: 208 | E20: 0 | F20: 95 | G20: 78
A21: 3112059 | B21: =VLOOKUP(A21,[1]SAEB!$A:$B,2,0) -> Cantagalo | C21: 2015 | D21: 281 | E21: 0 | F21: 85 | G21: 0
A22: 3112307 | B22: =VLOOKUP(A22,[1]SAEB!$A:$B,2,0) -> Capelinha | C22: 2015 | D22: 0 | E22: 0 | F22: 931 | G22: 0
A23: 3112703 | B23: =VLOOKUP(A23,[1]SAEB!$A:$B,2,0) -> Capitão Enéas | C23: 2015 | D23: 605 | E23: 384 | F23: 179 | G23: 82
A24: 3113008 | B24: =VLOOKUP(A24,[1]SAEB!$A:$B,2,0) -> Caraí | C24: 2015 | D24: 92 | E24: 217 | F24: 973 | G24: 442
A25: 3113503 | B25: =VLOOKUP(A25,[1]SAEB!$A:$B,2,0) -> Carbonita | C25: 2015 | D25: 264 | E25: 0 | F25: 127 | G25: 149
A26: 3113701 | B26: =VLOOKUP(A26,[1]SAEB!$A:$B,2,0) -> Carlos Chagas | C26: 2015 | D26: 908 | E26: 207 | F26: 414 | G26: 193
A27: 3113800 | B27: =VLOOKUP(A27,[1]SAEB!$A:$B,2,0) -> Carmésia | C27: 2015 | D27: 153 | E27: 164
A28: 3115458 | B28: =VLOOKUP(A28,[1]SAEB!$A:$B,2,0) -> Catuji | C28: 2015 | D28: 317 | E28: 0 | F28: 354 | G28: 0
A29: 3115474 | B29: =VLOOKUP(A29,[1]SAEB!$A:$B,2,0) -> Catuti | C29: 2015 | D29: 161 | E29: 0 | F29: 126 | G29: 107
A30: 3116100 | B30: =VLOOKUP(A30,[1]SAEB!$A:$B,2,0) -> Chapada do Norte | C30: 2015 | D30: 228 | E30: 0 | F30: 371 | G30: 0
A31: 3116159 | B31: =VLOOKUP(A31,[1]SAEB!$A:$B,2,0) -> Chapada Gaúcha | C31: 2015 | D31: 483 | E31: 108 | F31: 361 | G31: 321
A32: 3116506 | B32: =VLOOKUP(A32,[1]SAEB!$A:$B,2,0) -> Claro dos Poções | C32: 2015 | D32: 370 | E32: 0 | F32: 24 | G32: 21
A33: 3116803 | B33: =VLOOKUP(A33,[1]SAEB!$A:$B,2,0) -> Coluna | C33: 2015 | D33: 172 | E33: 0 | F33: 303 | G33: 0
A34: 3117009 | B34: =VLOOKUP(A34,[1]SAEB!$A:$B,2,0) -> Comercinho | C34: 2015 | D34: 302 | E34: 0 | F34: 255 | G34: 107
A35: 3118403 | B35: =VLOOKUP(A35,[1]SAEB!$A:$B,2,0) -> Conselheiro Pena | C35: 2015 | D35: 861 | E35: 105 | F35: 100 | G35: 64
A36: 3119104 | B36: =VLOOKUP(A36,[1]SAEB!$A:$B,2,0) -> Corinto | C36: 2015 | D36: 1520 | E36: 419 | F36: 12 | G36: 0
A37: 3119203 | B37: =VLOOKUP(A37,[1]SAEB!$A:$B,2,0) -> Coroaci | C37: 2015 | D37: 421 | E37: 85 | F37: 243 | G37: 198
A38: 3119500 | B38: =VLOOKUP(A38,[1]SAEB!$A:$B,2,0) -> Coronel Murta | C38: 2015 | D38: 477 | E38: 315 | F38: 55 | G38: 0
A39: 3120151 | B39: =VLOOKUP(A39,[1]SAEB!$A:$B,2,0) -> Crisólita | C39: 2015 | D39: 447 | E39: 217 | F39: 15 | G39: 0
... A48: 3123106 | B48: =VLOOKUP(A48,[1]SAEB!$A:$B,2,0) -> Dores de Guanhães | C48: 2015 | D48: 260 | E48: 0 | F48: 96 | G48: 0
...

Sheet IPCA
A1: ANO | B1: IPCA
A2: 2015 | B2: 4493.17
A3: 2016 | B3: 4775.7
A4: 2017 | B4: 4916.46
A5: 2018 | B5: 5100.61
A6: 2019 | B6: 5320.25
A7: 2020 | B7: 5560.59
A8: 2021 | B8: 6120.04
A9: 2022 | B9: 6474.09
A10: 2023 | B10: 6773.27
A11: 2024 | B11: 7100.5

Sheet TDI
A1: Ano | B1: Código do Município | C1: Nome do Município | D1: Localização | E1: TDI
A2: 2019 | B2: 3101003 | C2: Águas Vermelhas | D2: Total | E2: 1.8
A3: 2019 | B3: 3101003 | C3: Águas Vermelhas | D3: Urbana | E3: 1.4
A4: 2019 | B4: 3101003 | C4: Águas Vermelhas | D4: Rural | E4: 3.8
A5: 2019 | B5: 3101102 | C5: Aimorés | D5: Total | E5: 2.8
A6: 2019 | B6: 3101102 | C6: Aimorés | D6: Urbana | E6: 2.8
A7: 2019 | B7: 3101102 | C7: Aimorés | D7: Rural | E7: 2
A8: 2019 | B8: 3101706 | C8: Almenara | D8: Total | E8: 12.3
A9: 2019 | B9: 3101706 | C9: Almenara | D9: Urbana | E9: 11.9
A10: 2019 | B10: 3101706 | C10: Almenara | D10: Rural | E10: 14.7
A11: 2019 | B11: 3101805 | C11: Alpercata | D11: Total | E11: 6
A12: 2019 | B12: 3101805 | C12: Alpercata | D12: Urbana | E12: 5
A13: 2019 | B13: 3101805 | C13: Alpercata | D13: Rural | E13: 11
... A44: 2019 | B44: 3108602 | C44: Brasília de Minas | D44: Total | E44: 0.6
A45: 2019 | B45: 3108602 | C45: Brasília de Minas | D45: Urbana | E45: --
A46: 2019 | B46: 3108602 | C46: Brasília de Minas | D46: Rural | E46: 0.6
A47: 2019 | B47: 3109204 | C47: Buenópolis | D47: Total | E47: 1.6
A48: 2019 | B48: 3109204 | C48: Buenópolis | D48: Urbana | E48: 1.5
A49: 2019 | B49: 3109204 | C49: Buenópolis | D49: Rural | E49: 2.3
A50: 2019 | B50: 3109402 | C50: Buritizeiro | D50: Total | E50: 2
A51: 2019 | B51: 3109402 | C51: Buritizeiro | D51: Urbana | E51: 2
A52: 2019 | B52: 3109402 | C52: Buritizeiro | D52: Rural | E52: 1.7
A53: 2019 | B53: 3110806 | C53: Campanário | D53: Total | E53: 14
A54: 2019 | B54: 3110806 | C54: Campanário | D54: Urbana | E54: 14
A55: 2019 | B55: 3111150 | C55: Campo Azul | D55: Total | E55: 2.7
A56: 2019 | B56: 3111150 | C56: Campo Azul | D56: Urbana | E56: 1.7
A57: 2019 | B57: 3111150 | C57: Campo Azul | D57: Rural | E57: 4.8
... A581: 2021 | B581: 3108602 | C581: Brasília de Minas | D581: Total | E581: 0
A582: 2021 | B582: 3108602 | C582: Brasília de Minas | D582: Urbana | E582: --
A583: 2021 | B583: 3108602 | C583: Brasília de Minas | D583: Rural | E583: 0
A584: 2021 | B584: 3109204 | C584: Buenópolis | D584: Total | E584: 2.7
A585: 2021 | B585: 3109204 | C585: Buenópolis | D585: Urbana | E585: 2.5
A586: 2021 | B586: 3109204 | C586: Buenópolis | D586: Rural | E586: 5
A587: 2021 | B587: 3109402 | C587: Buritizeiro | D587: Total | E587: 1.8
A588: 2021 | B588: 3109402 | C588: Buritizeiro | D588: Urbana | E588: 1.9
A589: 2021 | B589: 3109402 | C589: Buritizeiro | D589: Rural | E589: 0.9
A590: 2021 | B590: 3110806 | C590: Campanário | D590: Total | E590: 8.3
A591: 2021 | B591: 3110806 | C591: Campanário | D591: Urbana | E591: 8.3
A592: 2021 | B592: 3111150 | C592: Campo Azul | D592: Total | E592: 0.8
A593: 2021 | B593: 3111150 | C593: Campo Azul | D593: Urbana | E593: 0
...
